2016-09-27 11:26:34,242 [ERROR][Thread-9:139849549657856] [exception.handle_uncaught_exception django.request:124] -- Internal Server Error: /wechat/
Traceback (most recent call last):
  File "/usr/local/lib/python3.5/dist-packages/django/core/handlers/exception.py", line 39, in inner
    response = get_response(request)
  File "/usr/local/lib/python3.5/dist-packages/django/core/handlers/base.py", line 187, in _get_response
    response = self.process_exception_by_middleware(e, request)
  File "/usr/local/lib/python3.5/dist-packages/django/core/handlers/base.py", line 185, in _get_response
    response = wrapped_callback(request, *callback_args, **callback_kwargs)
  File "/usr/local/lib/python3.5/dist-packages/django/views/decorators/csrf.py", line 58, in wrapped_view
    return view_func(*args, **kwargs)
  File "/home/syn/PycharmProjects/xinhua_vote/vote/views.py", line 86, in wechat_check
    resp = wechat_subscribe(request, xml_doc)
  File "/home/syn/PycharmProjects/xinhua_vote/vote/views.py", line 124, in wechat_subscribe
    token = wechat_get_token(request, 'internal')
  File "/home/syn/PycharmProjects/xinhua_vote/vote/views.py", line 244, in wechat_get_token
    decoded = json.loads(resp)
  File "/usr/lib/python3.5/json/__init__.py", line 312, in loads
    s.__class__.__name__))
TypeError: the JSON object must be str, not 'Response'
2016-09-27 11:26:39,173 [ERROR][Thread-10:139849558050560] [exception.handle_uncaught_exception django.request:124] -- Internal Server Error: /wechat/
Traceback (most recent call last):
  File "/usr/local/lib/python3.5/dist-packages/django/core/handlers/exception.py", line 39, in inner
    response = get_response(request)
  File "/usr/local/lib/python3.5/dist-packages/django/core/handlers/base.py", line 187, in _get_response
    response = self.process_exception_by_middleware(e, request)
  File "/usr/local/lib/python3.5/dist-packages/django/core/handlers/base.py", line 185, in _get_response
    response = wrapped_callback(request, *callback_args, **callback_kwargs)
  File "/usr/local/lib/python3.5/dist-packages/django/views/decorators/csrf.py", line 58, in wrapped_view
    return view_func(*args, **kwargs)
  File "/home/syn/PycharmProjects/xinhua_vote/vote/views.py", line 86, in wechat_check
    resp = wechat_subscribe(request, xml_doc)
  File "/home/syn/PycharmProjects/xinhua_vote/vote/views.py", line 124, in wechat_subscribe
    token = wechat_get_token(request, 'internal')
  File "/home/syn/PycharmProjects/xinhua_vote/vote/views.py", line 244, in wechat_get_token
    decoded = json.loads(resp)
  File "/usr/lib/python3.5/json/__init__.py", line 312, in loads
    s.__class__.__name__))
TypeError: the JSON object must be str, not 'Response'
2016-09-27 11:26:55,132 [ERROR][Thread-11:139849530275584] [exception.handle_uncaught_exception django.request:124] -- Internal Server Error: /wechat/
Traceback (most recent call last):
  File "/usr/local/lib/python3.5/dist-packages/django/core/handlers/exception.py", line 39, in inner
    response = get_response(request)
  File "/usr/local/lib/python3.5/dist-packages/django/core/handlers/base.py", line 187, in _get_response
    response = self.process_exception_by_middleware(e, request)
  File "/usr/local/lib/python3.5/dist-packages/django/core/handlers/base.py", line 185, in _get_response
    response = wrapped_callback(request, *callback_args, **callback_kwargs)
  File "/usr/local/lib/python3.5/dist-packages/django/views/decorators/csrf.py", line 58, in wrapped_view
    return view_func(*args, **kwargs)
  File "/home/syn/PycharmProjects/xinhua_vote/vote/views.py", line 86, in wechat_check
    resp = wechat_subscribe(request, xml_doc)
  File "/home/syn/PycharmProjects/xinhua_vote/vote/views.py", line 124, in wechat_subscribe
    token = wechat_get_token(request, 'internal')
  File "/home/syn/PycharmProjects/xinhua_vote/vote/views.py", line 244, in wechat_get_token
    decoded = json.loads(resp)
  File "/usr/lib/python3.5/json/__init__.py", line 312, in loads
    s.__class__.__name__))
TypeError: the JSON object must be str, not 'Response'
2016-09-27 11:27:38,915 [ERROR][Thread-8:140063792695040] [exception.handle_uncaught_exception django.request:124] -- Internal Server Error: /wechat/
Traceback (most recent call last):
  File "/usr/local/lib/python3.5/dist-packages/django/core/handlers/exception.py", line 39, in inner
    response = get_response(request)
  File "/usr/local/lib/python3.5/dist-packages/django/core/handlers/base.py", line 187, in _get_response
    response = self.process_exception_by_middleware(e, request)
  File "/usr/local/lib/python3.5/dist-packages/django/core/handlers/base.py", line 185, in _get_response
    response = wrapped_callback(request, *callback_args, **callback_kwargs)
  File "/usr/local/lib/python3.5/dist-packages/django/views/decorators/csrf.py", line 58, in wrapped_view
    return view_func(*args, **kwargs)
  File "/home/syn/PycharmProjects/xinhua_vote/vote/views.py", line 86, in wechat_check
    resp = wechat_subscribe(request, xml_doc)
  File "/home/syn/PycharmProjects/xinhua_vote/vote/views.py", line 134, in wechat_subscribe
    decoded = json.loads(resp)
  File "/usr/lib/python3.5/json/__init__.py", line 312, in loads
    s.__class__.__name__))
TypeError: the JSON object must be str, not 'Response'
2016-09-27 11:27:43,331 [ERROR][Thread-9:140063438292736] [exception.handle_uncaught_exception django.request:124] -- Internal Server Error: /wechat/
Traceback (most recent call last):
  File "/usr/local/lib/python3.5/dist-packages/django/db/backends/utils.py", line 64, in execute
    return self.cursor.execute(sql, params)
  File "/usr/local/lib/python3.5/dist-packages/django/db/backends/sqlite3/base.py", line 337, in execute
    return Database.Cursor.execute(self, query, params)
sqlite3.IntegrityError: UNIQUE constraint failed: vote_wechatconfig.tag

The above exception was the direct cause of the following exception:

Traceback (most recent call last):
  File "/usr/local/lib/python3.5/dist-packages/django/core/handlers/exception.py", line 39, in inner
    response = get_response(request)
  File "/usr/local/lib/python3.5/dist-packages/django/core/handlers/base.py", line 187, in _get_response
    response = self.process_exception_by_middleware(e, request)
  File "/usr/local/lib/python3.5/dist-packages/django/core/handlers/base.py", line 185, in _get_response
    response = wrapped_callback(request, *callback_args, **callback_kwargs)
  File "/usr/local/lib/python3.5/dist-packages/django/views/decorators/csrf.py", line 58, in wrapped_view
    return view_func(*args, **kwargs)
  File "/home/syn/PycharmProjects/xinhua_vote/vote/views.py", line 86, in wechat_check
    resp = wechat_subscribe(request, xml_doc)
  File "/home/syn/PycharmProjects/xinhua_vote/vote/views.py", line 124, in wechat_subscribe
    token = wechat_get_token(request, 'internal')
  File "/home/syn/PycharmProjects/xinhua_vote/vote/views.py", line 271, in wechat_get_token
    token_record.save()
  File "/usr/local/lib/python3.5/dist-packages/django/db/models/base.py", line 796, in save
    force_update=force_update, update_fields=update_fields)
  File "/usr/local/lib/python3.5/dist-packages/django/db/models/base.py", line 824, in save_base
    updated = self._save_table(raw, cls, force_insert, force_update, using, update_fields)
  File "/usr/local/lib/python3.5/dist-packages/django/db/models/base.py", line 908, in _save_table
    result = self._do_insert(cls._base_manager, using, fields, update_pk, raw)
  File "/usr/local/lib/python3.5/dist-packages/django/db/models/base.py", line 947, in _do_insert
    using=using, raw=raw)
  File "/usr/local/lib/python3.5/dist-packages/django/db/models/manager.py", line 85, in manager_method
    return getattr(self.get_queryset(), name)(*args, **kwargs)
  File "/usr/local/lib/python3.5/dist-packages/django/db/models/query.py", line 1045, in _insert
    return query.get_compiler(using=using).execute_sql(return_id)
  File "/usr/local/lib/python3.5/dist-packages/django/db/models/sql/compiler.py", line 1054, in execute_sql
    cursor.execute(sql, params)
  File "/usr/local/lib/python3.5/dist-packages/django/db/backends/utils.py", line 79, in execute
    return super(CursorDebugWrapper, self).execute(sql, params)
  File "/usr/local/lib/python3.5/dist-packages/django/db/backends/utils.py", line 64, in execute
    return self.cursor.execute(sql, params)
  File "/usr/local/lib/python3.5/dist-packages/django/db/utils.py", line 94, in __exit__
    six.reraise(dj_exc_type, dj_exc_value, traceback)
  File "/usr/local/lib/python3.5/dist-packages/django/utils/six.py", line 685, in reraise
    raise value.with_traceback(tb)
  File "/usr/local/lib/python3.5/dist-packages/django/db/backends/utils.py", line 64, in execute
    return self.cursor.execute(sql, params)
  File "/usr/local/lib/python3.5/dist-packages/django/db/backends/sqlite3/base.py", line 337, in execute
    return Database.Cursor.execute(self, query, params)
django.db.utils.IntegrityError: UNIQUE constraint failed: vote_wechatconfig.tag
2016-09-27 11:36:58,696 [ERROR][Thread-2:139944607995648] [exception.handle_uncaught_exception django.request:124] -- Internal Server Error: /wechat/
Traceback (most recent call last):
  File "/usr/local/lib/python3.5/dist-packages/django/core/handlers/exception.py", line 39, in inner
    response = get_response(request)
  File "/usr/local/lib/python3.5/dist-packages/django/core/handlers/base.py", line 198, in _get_response
    "returned None instead." % (callback.__module__, view_name)
ValueError: The view vote.views.wechat_check didn't return an HttpResponse object. It returned None instead.
2016-09-27 12:43:09,942 [WARNING][Thread-2:140651080734464] [base.get_response django.request:152] -- Not Found: /http:/zc.qq.com/cgi-bin/common/attr
2016-09-27 13:16:50,081 [ERROR][Thread-7:140612318709504] [exception.handle_uncaught_exception django.request:124] -- Internal Server Error: /list/
Traceback (most recent call last):
  File "/home/syn/PycharmProjects/xinhua_vote/vote/views.py", line 299, in show_main_list
    login()
  File "/home/syn/PycharmProjects/xinhua_vote/vote/views.py", line 26, in login
    redirect_url = api.get_authorize_login_url(scope=("snsapi_login",))
  File "/usr/local/lib/python3.5/dist-packages/py3weixin/oauth2.py", line 97, in get_authorize_login_url
    return req.get_authorize_login_url(scope=scope, state=state)
  File "/usr/local/lib/python3.5/dist-packages/py3weixin/oauth2.py", line 171, in get_authorize_login_url
    error_data = error_parser(response.content, encoding)
  File "/usr/local/lib/python3.5/dist-packages/py3weixin/helper.py", line 205, in error_parser
    html = unicode(error_html, encoding or 'gbk')
NameError: name 'unicode' is not defined

During handling of the above exception, another exception occurred:

Traceback (most recent call last):
  File "/usr/local/lib/python3.5/dist-packages/django/core/handlers/exception.py", line 39, in inner
    response = get_response(request)
  File "/usr/local/lib/python3.5/dist-packages/django/core/handlers/base.py", line 187, in _get_response
    response = self.process_exception_by_middleware(e, request)
  File "/usr/local/lib/python3.5/dist-packages/django/core/handlers/base.py", line 185, in _get_response
    response = wrapped_callback(request, *callback_args, **callback_kwargs)
  File "/home/syn/PycharmProjects/xinhua_vote/vote/views.py", line 302, in show_main_list
    return render_to_response("vote/notice.html")
  File "/usr/local/lib/python3.5/dist-packages/django/shortcuts.py", line 21, in render_to_response
    content = loader.render_to_string(template_name, context, using=using)
  File "/usr/local/lib/python3.5/dist-packages/django/template/loader.py", line 67, in render_to_string
    template = get_template(template_name, using=using)
  File "/usr/local/lib/python3.5/dist-packages/django/template/loader.py", line 25, in get_template
    raise TemplateDoesNotExist(template_name, chain=chain)
django.template.exceptions.TemplateDoesNotExist: vote/notice.html
2016-09-27 13:17:50,908 [ERROR][Thread-15:140612318709504] [exception.handle_uncaught_exception django.request:124] -- Internal Server Error: /list/
Traceback (most recent call last):
  File "/home/syn/PycharmProjects/xinhua_vote/vote/views.py", line 299, in show_main_list
    login()
  File "/home/syn/PycharmProjects/xinhua_vote/vote/views.py", line 26, in login
    redirect_url = api.get_authorize_login_url(scope=("snsapi_login",))
  File "/usr/local/lib/python3.5/dist-packages/py3weixin/oauth2.py", line 97, in get_authorize_login_url
    return req.get_authorize_login_url(scope=scope, state=state)
  File "/usr/local/lib/python3.5/dist-packages/py3weixin/oauth2.py", line 171, in get_authorize_login_url
    error_data = error_parser(response.content, encoding)
  File "/usr/local/lib/python3.5/dist-packages/py3weixin/helper.py", line 205, in error_parser
    html = unicode(error_html, encoding or 'gbk')
NameError: name 'unicode' is not defined

During handling of the above exception, another exception occurred:

Traceback (most recent call last):
  File "/usr/local/lib/python3.5/dist-packages/django/core/handlers/exception.py", line 39, in inner
    response = get_response(request)
  File "/usr/local/lib/python3.5/dist-packages/django/core/handlers/base.py", line 187, in _get_response
    response = self.process_exception_by_middleware(e, request)
  File "/usr/local/lib/python3.5/dist-packages/django/core/handlers/base.py", line 185, in _get_response
    response = wrapped_callback(request, *callback_args, **callback_kwargs)
  File "/home/syn/PycharmProjects/xinhua_vote/vote/views.py", line 302, in show_main_list
    return render_to_response("vote/notice.html")
  File "/usr/local/lib/python3.5/dist-packages/django/shortcuts.py", line 21, in render_to_response
    content = loader.render_to_string(template_name, context, using=using)
  File "/usr/local/lib/python3.5/dist-packages/django/template/loader.py", line 67, in render_to_string
    template = get_template(template_name, using=using)
  File "/usr/local/lib/python3.5/dist-packages/django/template/loader.py", line 25, in get_template
    raise TemplateDoesNotExist(template_name, chain=chain)
django.template.exceptions.TemplateDoesNotExist: vote/notice.html
2016-09-27 13:18:34,465 [WARNING][Thread-66:140611788793600] [base.get_response django.request:152] -- Not Found: /admin/vote/candidate/3/delete/
2016-09-27 13:38:56,925 [ERROR][Thread-7:140693773711104] [exception.handle_uncaught_exception django.request:124] -- Internal Server Error: /login/
Traceback (most recent call last):
  File "/home/syn/PycharmProjects/xinhua_vote/vote/views.py", line 304, in login
    login()
TypeError: login() missing 1 required positional argument: 'request'

During handling of the above exception, another exception occurred:

Traceback (most recent call last):
  File "/usr/local/lib/python3.5/dist-packages/django/core/handlers/exception.py", line 39, in inner
    response = get_response(request)
  File "/usr/local/lib/python3.5/dist-packages/django/core/handlers/base.py", line 187, in _get_response
    response = self.process_exception_by_middleware(e, request)
  File "/usr/local/lib/python3.5/dist-packages/django/core/handlers/base.py", line 185, in _get_response
    response = wrapped_callback(request, *callback_args, **callback_kwargs)
  File "/home/syn/PycharmProjects/xinhua_vote/vote/views.py", line 307, in login
    return render_to_response("vote/notice.html")
  File "/usr/local/lib/python3.5/dist-packages/django/shortcuts.py", line 21, in render_to_response
    content = loader.render_to_string(template_name, context, using=using)
  File "/usr/local/lib/python3.5/dist-packages/django/template/loader.py", line 67, in render_to_string
    template = get_template(template_name, using=using)
  File "/usr/local/lib/python3.5/dist-packages/django/template/loader.py", line 25, in get_template
    raise TemplateDoesNotExist(template_name, chain=chain)
django.template.exceptions.TemplateDoesNotExist: vote/notice.html
2016-09-27 13:40:11,007 [ERROR][Thread-7:139844367042304] [exception.handle_uncaught_exception django.request:124] -- Internal Server Error: /login/
Traceback (most recent call last):
  File "/usr/local/lib/python3.5/dist-packages/django/core/handlers/exception.py", line 39, in inner
    response = get_response(request)
  File "/usr/local/lib/python3.5/dist-packages/django/core/handlers/base.py", line 198, in _get_response
    "returned None instead." % (callback.__module__, view_name)
ValueError: The view vote.views.login didn't return an HttpResponse object. It returned None instead.
2016-09-27 13:41:43,749 [ERROR][Thread-12:139844350256896] [exception.handle_uncaught_exception django.request:124] -- Internal Server Error: /login/
Traceback (most recent call last):
  File "/usr/local/lib/python3.5/dist-packages/django/core/handlers/exception.py", line 39, in inner
    response = get_response(request)
  File "/usr/local/lib/python3.5/dist-packages/django/core/handlers/base.py", line 198, in _get_response
    "returned None instead." % (callback.__module__, view_name)
ValueError: The view vote.views.login didn't return an HttpResponse object. It returned None instead.
2016-09-27 13:48:21,280 [ERROR][Thread-7:140380166424320] [exception.handle_uncaught_exception django.request:124] -- Internal Server Error: /login/
Traceback (most recent call last):
  File "/usr/local/lib/python3.5/dist-packages/django/core/handlers/exception.py", line 39, in inner
    response = get_response(request)
  File "/usr/local/lib/python3.5/dist-packages/django/core/handlers/base.py", line 198, in _get_response
    "returned None instead." % (callback.__module__, view_name)
ValueError: The view vote.views.login didn't return an HttpResponse object. It returned None instead.
2016-09-27 13:51:10,173 [ERROR][Thread-12:140380166424320] [exception.handle_uncaught_exception django.request:124] -- Internal Server Error: /login/
Traceback (most recent call last):
  File "/usr/local/lib/python3.5/dist-packages/django/core/handlers/exception.py", line 39, in inner
    response = get_response(request)
  File "/usr/local/lib/python3.5/dist-packages/django/core/handlers/base.py", line 198, in _get_response
    "returned None instead." % (callback.__module__, view_name)
ValueError: The view vote.views.login didn't return an HttpResponse object. It returned None instead.
2016-09-27 13:51:44,695 [WARNING][Thread-16:140380158031616] [base.get_response django.request:152] -- Not Found: /
2016-09-27 13:51:54,692 [WARNING][Thread-17:140380158031616] [base.get_response django.request:152] -- Not Found: /
2016-09-27 13:51:54,759 [WARNING][Thread-15:140380166424320] [base.get_response django.request:152] -- Not Found: /authorization/
2016-09-27 13:51:55,188 [WARNING][Thread-18:140380166424320] [base.get_response django.request:152] -- Not Found: /authorization/
2016-09-27 13:51:55,645 [WARNING][Thread-20:140380158031616] [base.get_response django.request:152] -- Not Found: /authorization/
2016-09-27 13:59:17,879 [ERROR][Thread-8:139978554210048] [exception.handle_uncaught_exception django.request:124] -- Internal Server Error: /authorization/
Traceback (most recent call last):
  File "/usr/local/lib/python3.5/dist-packages/django/core/handlers/exception.py", line 39, in inner
    response = get_response(request)
  File "/usr/local/lib/python3.5/dist-packages/django/core/handlers/base.py", line 187, in _get_response
    response = self.process_exception_by_middleware(e, request)
  File "/usr/local/lib/python3.5/dist-packages/django/core/handlers/base.py", line 185, in _get_response
    response = wrapped_callback(request, *callback_args, **callback_kwargs)
  File "/home/syn/PycharmProjects/xinhua_vote/vote/views.py", line 39, in authorization
    return json.loads(resp)
  File "/usr/lib/python3.5/json/__init__.py", line 312, in loads
    s.__class__.__name__))
TypeError: the JSON object must be str, not 'Response'
2016-09-27 13:59:17,910 [ERROR][Thread-7:139978772309760] [exception.handle_uncaught_exception django.request:124] -- Internal Server Error: /authorization/
Traceback (most recent call last):
  File "/usr/local/lib/python3.5/dist-packages/django/core/handlers/exception.py", line 39, in inner
    response = get_response(request)
  File "/usr/local/lib/python3.5/dist-packages/django/core/handlers/base.py", line 187, in _get_response
    response = self.process_exception_by_middleware(e, request)
  File "/usr/local/lib/python3.5/dist-packages/django/core/handlers/base.py", line 185, in _get_response
    response = wrapped_callback(request, *callback_args, **callback_kwargs)
  File "/home/syn/PycharmProjects/xinhua_vote/vote/views.py", line 39, in authorization
    return json.loads(resp)
  File "/usr/lib/python3.5/json/__init__.py", line 312, in loads
    s.__class__.__name__))
TypeError: the JSON object must be str, not 'Response'
2016-09-27 14:27:45,499 [WARNING][Thread-16:139694515926784] [base.get_response django.request:152] -- Not Found: /
2016-09-27 14:27:45,800 [WARNING][Thread-18:139694515926784] [base.get_response django.request:152] -- Not Found: /
2016-09-27 14:27:48,902 [WARNING][Thread-77:139694630741760] [base.get_response django.request:152] -- Not Found: /
2016-09-27 14:46:36,934 [WARNING][Thread-5:139726262564608] [base.get_response django.request:152] -- Not Found: /content/33
2016-09-27 14:47:12,657 [WARNING][Thread-5:140287240070912] [base.get_response django.request:152] -- Not Found: /content/33/
2016-09-27 14:48:28,599 [WARNING][Thread-36:140287206237952] [base.get_response django.request:152] -- Not Found: /content/33/
2016-09-27 14:48:37,878 [WARNING][Thread-37:140287214630656] [base.get_response django.request:152] -- Not Found: /content/31/
2016-09-27 14:48:45,851 [WARNING][Thread-42:140287206237952] [base.get_response django.request:152] -- Not Found: /content/27/
2016-09-27 14:51:08,495 [WARNING][Thread-7:139931611563776] [base.get_response django.request:152] -- Not Found: /content/28/
2016-09-27 14:51:13,364 [WARNING][Thread-8:139931603171072] [base.get_response django.request:152] -- Not Found: /content/28/
2016-09-27 14:51:27,521 [WARNING][Thread-14:139931359893248] [base.get_response django.request:152] -- Not Found: /content/23/
2016-09-27 14:52:18,657 [WARNING][Thread-42:139950888572672] [base.get_response django.request:152] -- Not Found: /favicon.ico
2016-09-27 14:52:18,954 [WARNING][Thread-43:139950888572672] [base.get_response django.request:152] -- Not Found: /content/23/
2016-09-27 14:58:11,545 [WARNING][Thread-32:139811358680832] [base.get_response django.request:152] -- Not Found: /
2016-09-27 15:02:29,791 [WARNING][Thread-9:140603455805184] [base.get_response django.request:152] -- Not Found: /
2016-09-27 15:09:09,848 [ERROR][Thread-13:140009996678912] [exception.handle_uncaught_exception django.request:124] -- Internal Server Error: /admin/vote/followinfo/
Traceback (most recent call last):
  File "/usr/local/lib/python3.5/dist-packages/django/db/backends/utils.py", line 64, in execute
    return self.cursor.execute(sql, params)
  File "/usr/local/lib/python3.5/dist-packages/django/db/backends/sqlite3/base.py", line 337, in execute
    return Database.Cursor.execute(self, query, params)
sqlite3.OperationalError: no such table: vote_followinfo

The above exception was the direct cause of the following exception:

Traceback (most recent call last):
  File "/usr/local/lib/python3.5/dist-packages/django/core/handlers/exception.py", line 39, in inner
    response = get_response(request)
  File "/usr/local/lib/python3.5/dist-packages/django/core/handlers/base.py", line 187, in _get_response
    response = self.process_exception_by_middleware(e, request)
  File "/usr/local/lib/python3.5/dist-packages/django/core/handlers/base.py", line 185, in _get_response
    response = wrapped_callback(request, *callback_args, **callback_kwargs)
  File "/usr/local/lib/python3.5/dist-packages/django/contrib/admin/options.py", line 544, in wrapper
    return self.admin_site.admin_view(view)(*args, **kwargs)
  File "/usr/local/lib/python3.5/dist-packages/django/utils/decorators.py", line 149, in _wrapped_view
    response = view_func(request, *args, **kwargs)
  File "/usr/local/lib/python3.5/dist-packages/django/views/decorators/cache.py", line 57, in _wrapped_view_func
    response = view_func(request, *args, **kwargs)
  File "/usr/local/lib/python3.5/dist-packages/django/contrib/admin/sites.py", line 211, in inner
    return view(request, *args, **kwargs)
  File "/usr/local/lib/python3.5/dist-packages/django/utils/decorators.py", line 67, in _wrapper
    return bound_func(*args, **kwargs)
  File "/usr/local/lib/python3.5/dist-packages/django/utils/decorators.py", line 149, in _wrapped_view
    response = view_func(request, *args, **kwargs)
  File "/usr/local/lib/python3.5/dist-packages/django/utils/decorators.py", line 63, in bound_func
    return func.__get__(self, type(self))(*args2, **kwargs2)
  File "/usr/local/lib/python3.5/dist-packages/django/contrib/admin/options.py", line 1543, in changelist_view
    self.list_max_show_all, self.list_editable, self,
  File "/usr/local/lib/python3.5/dist-packages/django/contrib/admin/views/main.py", line 79, in __init__
    self.get_results(request)
  File "/usr/local/lib/python3.5/dist-packages/django/contrib/admin/views/main.py", line 172, in get_results
    result_count = paginator.count
  File "/usr/local/lib/python3.5/dist-packages/django/utils/functional.py", line 35, in __get__
    res = instance.__dict__[self.name] = self.func(instance)
  File "/usr/local/lib/python3.5/dist-packages/django/core/paginator.py", line 72, in count
    return self.object_list.count()
  File "/usr/local/lib/python3.5/dist-packages/django/db/models/query.py", line 369, in count
    return self.query.get_count(using=self.db)
  File "/usr/local/lib/python3.5/dist-packages/django/db/models/sql/query.py", line 476, in get_count
    number = obj.get_aggregation(using, ['__count'])['__count']
  File "/usr/local/lib/python3.5/dist-packages/django/db/models/sql/query.py", line 457, in get_aggregation
    result = compiler.execute_sql(SINGLE)
  File "/usr/local/lib/python3.5/dist-packages/django/db/models/sql/compiler.py", line 835, in execute_sql
    cursor.execute(sql, params)
  File "/usr/local/lib/python3.5/dist-packages/django/db/backends/utils.py", line 79, in execute
    return super(CursorDebugWrapper, self).execute(sql, params)
  File "/usr/local/lib/python3.5/dist-packages/django/db/backends/utils.py", line 64, in execute
    return self.cursor.execute(sql, params)
  File "/usr/local/lib/python3.5/dist-packages/django/db/utils.py", line 94, in __exit__
    six.reraise(dj_exc_type, dj_exc_value, traceback)
  File "/usr/local/lib/python3.5/dist-packages/django/utils/six.py", line 685, in reraise
    raise value.with_traceback(tb)
  File "/usr/local/lib/python3.5/dist-packages/django/db/backends/utils.py", line 64, in execute
    return self.cursor.execute(sql, params)
  File "/usr/local/lib/python3.5/dist-packages/django/db/backends/sqlite3/base.py", line 337, in execute
    return Database.Cursor.execute(self, query, params)
django.db.utils.OperationalError: no such table: vote_followinfo
2016-09-27 15:10:40,365 [WARNING][Thread-2:139922136958720] [base.get_response django.request:152] -- Not Found: /http:/zc.qq.com/cgi-bin/common/attr
2016-09-27 15:34:01,575 [WARNING][Thread-200:139734873532160] [base.get_response django.request:152] -- Not Found: /
